Workbook
Name Market_CAGR: Inputs!$B$8
Name Discount_Rate: Inputs!$B$42
Name Revenue_Y5: '5-Year Projection'!F$15
Name EBITDA_Y5: '5-Year Projection'!F$28
Name Net_Income_Y5: '5-Year Projection'!F$36
Name Team_ARPU: Inputs!$B$31
Name Enterprise_ACV: Inputs!$B$30
Name Gross_Margin: Inputs!$B$37
Name Team_LTV: 'Unit Economics'!B$10
Name Enterprise_LTV: 'Unit Economics'!B$23

Sheet Inputs
A1: NEURALMIND — KEY MODEL INPUTS
A4: MARKET ASSUMPTIONS
A6: Total Addressable Market 2025 ($B) | B6: 7.65
A7: Projected TAM 2030 ($B) | B7: 22.2
A8: Market CAGR | B8: 0.238
A9: Cloud Share of Market 2025 | B9: 0.7247
A10: Enterprise AI Market 2024 ($B) | B10: 24
A11: Developer AI Adoption 2025 | B11: 0.91
A12: Gartner 2028 Developer Adoption | B12: 0.75
A13: Code Generation Use-Case Share | B13: 0.41
A14: AI Project Cancellation Rate 2027 | B14: 0.4
A16: 5-YEAR FINANCIAL PROJECTIONS
A18: Year | B18: Revenue ($) | C18: Cost ($) | D18: Users (Seats)
A19: Year 1 | B19: 0 | C19: 85000 | D19: 0
A20: Year 2 | B20: 45000 | C20: 180000 | D20: 50
A21: Year 3 | B21: 320000 | C21: 380000 | D21: 250
A22: Year 4 | B22: 950000 | C22: 620000 | D22: 750
A23: Year 5 | B23: 2400000 | C23: 1100000 | D23: 2000
A25: PRICING ASSUMPTIONS
A27: OSS Price ($/mo) | B27: 0
A28: Team Price ($/user/mo) | B28: 25
A29: Enterprise Min Price ($/yr) | B29: 50000
A30: Avg Enterprise Deal ($/yr) | B30: 75000
A31: Blended Team ARPU ($/user/mo) | B31: 22
A32: Annual Price Escalator | B32: 0.05
A34: GROWTH & MARGIN ASSUMPTIONS
A36: Revenue Growth Y2→Y3 | B36: 6.1111111
A37: Gross Margin Target | B37: 0.75
A38: R&D % of Revenue | B38: 0.55
A39: S&M % of Revenue | B39: 0.3
A40: G&A % of Revenue | B40: 0.15
A41: Tax Rate | B41: 0.21
A42: Discount Rate (WACC) | B42: 0.12
A44: SEGMENT SENSITIVITY
A46: Engineering Teams — Total | B46: 5000
A47: Engineering Teams — Captured Y5 | B47: 0.05
A48: Security-Sensitive — Total | B48: 1200
A49: Security-Sensitive — Captured Y5 | B49: 0.03
A50: Platform/Infra — Total | B50: 3000
A51: Platform/Infra — Captured Y5 | B51: 0.04
...

Sheet 5-Year Projection
A1: 5-YEAR P&L PROJECTION
A3: Line Item | B3: Year 1 | C3: Year 2 | D3: Year 3 | E3: Year 4 | F3: Year 5
A5: REVENUE DRIVERS
A7: OSS Users (cumulative) | B7: 0 | C7: ='5-Year Projection'!B7+250 | D7: =D7+250*(3-1) | E7: =E7+250*(4-1) | F7: =F7+250*(5-1)
A8: Team Seats | B8: 0 | C8: =Inputs!B20 | D8: =Inputs!B21 | E8: =Inputs!B22 | F8: =Inputs!B23
A9: Enterprise Deals | B9: 0 | C9: 0 | D9: 10 | E9: =D9+ROUND(D9*0.6,0) | F9: =E9+ROUND(E9*0.6,0)
A11: REVENUE
A12: Team Subscription Revenue | B12: 0 | C12: =C8*Inputs!$B$31*12 | D12: =D8*Inputs!$B$31*12 | E12: =E8*Inputs!$B$31*12 | F12: =F8*Inputs!$B$31*12
A13: Enterprise Revenue | B13: =B9*Inputs!$B$30 | C13: =C9*Inputs!$B$30 | D13: =D9*Inputs!$B$30 | E13: =E9*Inputs!$B$30 | F13: =F9*Inputs!$B$30
A14: OSS / Grants / Other | B14: 0 | C14: 0 | D14: =D8*2 | E14: =E8*2 | F14: =F8*2
A15: Total Revenue | B15: =SUM(B12:B14) | C15: =SUM(C12:C14) | D15: =SUM(D12:D14) | E15: =SUM(E12:E14) | F15: =SUM(F12:F14)
A17: Cost of Revenue | B17: =B15*(1-Inputs!$B$37) | C17: =C15*(1-Inputs!$B$37) | D17: =D15*(1-Inputs!$B$37) | E17: =E15*(1-Inputs!$B$37) | F17: =F15*(1-Inputs!$B$37)
A18: Gross Profit | B18: =B15-B17 | C18: =C15-C17 | D18: =D15-D17 | E18: =E15-E17 | F18: =F15-F17
A19: Gross Margin % | B19: =IF(B15=0,0,B18/B15) | C19: =IF(C15=0,0,C18/C15) | D19: =IF(D15=0,0,D18/D15) | E19: =IF(E15=0,0,E18/E15) | F19: =IF(F15=0,0,F18/F15)
A21: OPERATING EXPENSES
A23: R&D | B23: =B15*Inputs!$B$38 | C23: =C15*Inputs!$B$38 | D23: =D15*Inputs!$B$38 | E23: =E15*Inputs!$B$38 | F23: =F15*Inputs!$B$38
A24: Sales & Marketing | B24: =B15*Inputs!$B$39 | C24: =C15*Inputs!$B$39 | D24: =D15*Inputs!$B$39 | E24: =E15*Inputs!$B$39 | F24: =F15*Inputs!$B$39
A25: General & Administrative | B25: =B15*Inputs!$B$40 | C25: =C15*Inputs!$B$40 | D25: =D15*Inputs!$B$40 | E25: =E15*Inputs!$B$40 | F25: =F15*Inputs!$B$40
A26: Total OpEx | B26: =SUM(B23:B25) | C26: =SUM(C23:C25) | D26: =SUM(D23:D25) | E26: =SUM(E23:E25) | F26: =SUM(F23:F25)
A28: EBITDA | B28: =B18-B26 | C28: =C18-C26 | D28: =D18-D26 | E28: =E18-E26 | F28: =F18-F26
A29: EBITDA Margin % | B29: =IF(B15=0,0,B28/B15) | C29: =IF(C15=0,0,C28/C15) | D29: =IF(D15=0,0,D28/D15) | E29: =IF(E15=0,0,E28/E15) | F29: =IF(F15=0,0,F28/F15)
A31: Depreciation & Amortization | B31: =B23*0.10 | C31: =C23*0.10 | D31: =D23*0.10 | E31: =E23*0.10 | F31: =F23*0.10
A32: EBIT | B32: =B28-B31 | C32: =C28-C31 | D32: =D28-D31 | E32: =E28-E31 | F32: =F28-F31
A33: Interest Expense | B33: 0 | C33: 0 | D33: 5000 | E33: 5000 | F33: 5000
A34: EBT | B34: =B32-B33 | C34: =C32-C33 | D34: =D32-D33 | E34: =E32-E33 | F34: =F32-F33
A35: Tax | B35: =MAX(B34*Inputs!$B$41,0) | C35: =MAX(C34*Inputs!$B$41,0) | D35: =MAX(D34*Inputs!$B$41,0) | E35: =MAX(E34*Inputs!$B$41,0) | F35: =MAX(F34*Inputs!$B$41,0)
A36: Net Income | B36: =B34-B35 | C36: =C34-C35 | D36: =D34-D35 | E36: =E34-E35 | F36: =F34-F35
A37: Net Margin % | B37: =IF(B15=0,0,B36/B15) | C37: =IF(C15=0,0,C36/C15) | D37: =IF(D15=0,0,D36/D15) | E37: =IF(E15=0,0,E36/E15) | F37: =IF(F15=0,0,F36/F15)

Sheet Pricing Model
A1: PRICING MODEL — OSS / TEAM / ENTERPRISE
A3: Feature / Metric | B3: OSS | C3: Team | D3: Enterprise
A4: Price | B4: 0 | C4: =Inputs!$B$28 | D4: Custom
A5: Billing | B5: Free | C5: Annual | D5: Annual
A6: Users | B6: Unlimited | C6: Per-seat | D6: Custom
A7: Graph Intelligence | B7: ✓ | C7: ✓ | D7: ✓
A8: Multi-Language Support | B8: ✓ | C8: ✓ | D8: ✓
A9: RBAC | B9: — | C9: ✓ | D9: ✓
A10: SSO | B10: — | C10: ✓ | D10: ✓
A11: Audit Trail | B11: — | C11: ✓ | D11: ✓
A12: Air-Gap / On-Prem | B12: Manual | C12: — | D12: ✓
A13: Custom Parsers | B13: — | C13: — | D13: ✓
A14: Dedicated CSM | B14: — | C14: — | D14: ✓
A15: SLA | B15: — | C15: — | D15: ✓
A16: Annual Contract Value | B16: $0 | C16: =Inputs!$B$31*12 | D16: =Inputs!$B$30
A19: REVENUE MIX PROJECTION
A21: Year | B21: Year 1 | C21: Year 2 | D21: Year 3 | E21: Year 4 | F21: Year 5
A23: Team ARR | B23: ='5-Year Projection'!B12 | C23: ='5-Year Projection'!C12 | D23: ='5-Year Projection'!D12 | E23: ='5-Year Projection'!E12 | F23: ='5-Year Projection'!F12
A24: Enterprise ARR | B24: ='5-Year Projection'!B13 | C24: ='5-Year Projection'!C13 | D24: ='5-Year Projection'!D13 | E24: ='5-Year Projection'!E13 | F24: ='5-Year Projection'!F13
A25: Total ARR | B25: =B23+B24 | C25: =C23+C24 | D25: =D23+D24 | E25: =E23+E24 | F25: =F23+F24
A27: Team % of Revenue | B27: =IF(B25=0,0,B23/B25) | C27: =IF(C25=0,0,C23/C25) | D27: =IF(D25=0,0,D23/D25) | E27: =IF(E25=0,0,E23/E25) | F27: =IF(F25=0,0,F23/F25)
A28: Enterprise % of Revenue | B28: =IF(B25=0,0,B24/B25) | C28: =IF(C25=0,0,C24/C25) | D28: =IF(D25=0,0,D24/D25) | E28: =IF(E25=0,0,E24/E25) | F28: =IF(F25=0,0,F24/F25)

Sheet Segment Sensitivity
A1: SEGMENT SENSITIVITY ANALYSIS
A3: Penetration Rate Sensitivity — Team Revenue Y5
A5: Penetration % ↓ / Avg Price → | B5: 15 | C5: 20 | D5: 25 | E5: 30 | F5: 35
A6: 0.02 | B6: =Inputs!$B$46*A6*B5*12 | C6: =Inputs!$B$46*A6*C5*12 | D6: =Inputs!$B$46*A6*D5*12 | E6: =Inputs!$B$46*A6*E5*12 | F6: =Inputs!$B$46*A6*F5*12
A7: 0.03 | B7: =Inputs!$B$46*A7*B5*12 | C7: =Inputs!$B$46*A7*C5*12 | D7: =Inputs!$B$46*A7*D5*12 | E7: =Inputs!$B$46*A7*E5*12 | F7: =Inputs!$B$46*A7*F5*12
A8: 0.05 | B8: =Inputs!$B$46*A8*B5*12 | C8: =Inputs!$B$46*A8*C5*12 | D8: =Inputs!$B$46*A8*D5*12 | E8: =Inputs!$B$46*A8*E5*12 | F8: =Inputs!$B$46*A8*F5*12
A9: 0.08 | B9: =Inputs!$B$46*A9*B5*12 | C9: =Inputs!$B$46*A9*C5*12 | D9: =Inputs!$B$46*A9*D5*12 | E9: =Inputs!$B$46*A9*E5*12 | F9: =Inputs!$B$46*A9*F5*12
A10: 0.1 | B10: =Inputs!$B$46*A10*B5*12 | C10: =Inputs!$B$46*A10*C5*12 | D10: =Inputs!$B$46*A10*D5*12 | E10: =Inputs!$B$46*A10*E5*12 | F10: =Inputs!$B$46*A10*F5*12
A12: Enterprise Deal Size Sensitivity — Revenue Y5
A14: Price ↓ / Deals → | B14: 10 | C14: 20 | D14: 30 | E14: 50 | F14: 75
A15: 30000 | B15: =A15*B14 | C15: =A15*C14 | D15: =A15*D14 | E15: =A15*E14 | F15: =A15*F14
A16: 50000 | B16: =A16*B14 | C16: =A16*C14 | D16: =A16*D14 | E16: =A16*E14 | F16: =A16*F14
A17: 75000 | B17: =A17*B14 | C17: =A17*C14 | D17: =A17*D14 | E17: =A17*E14 | F17: =A17*F14
A18: 100000 | B18: =A18*B14 | C18: =A18*C14 | D18: =A18*D14 | E18: =A18*E14 | F18: =A18*F14
A19: 150000 | B19: =A19*B14 | C19: =A19*C14 | D19: =A19*D14 | E19: =A19*E14 | F19: =A19*F14
A23: SEGMENT CAPTURE SUMMARY (Year 5)
A25: Segment | B25: Total Addressable | C25: Capture Rate | D25: Captured Units | E25: Avg Revenue/Unit | F25: Total Revenue
A26: Engineering Teams | B26: =Inputs!B46 | C26: =Inputs!B47 | D26: =B26*C26 | E26: =Inputs!$B$31*12 | F26: =D26*E26
A27: Security-Sensitive | B27: =Inputs!B48 | C27: =Inputs!B49 | D27: =B27*C27 | E27: =Inputs!$B$30 | F27: =D27*E27
A28: Platform/Infra | B28: =Inputs!B50 | C28: =Inputs!B51 | D28: =B28*C28 | E28: =Inputs!$B$31*12 | F28: =D28*E28
A29: Business/Management | B29: =Inputs!B52 | C29: =Inputs!B53 | D29: =B29*C29 | E29: =Inputs!$B$30*0.5 | F29: =D29*E29
A30: Total | B30: =SUM(B26:B29) | C30: =SUM(C26:C29) | D30: =SUM(D26:D29) | E30: =SUM(E26:E29) | F30: =SUM(F26:F29)

Sheet Unit Economics
A1: UNIT ECONOMICS
A3: TEAM TIER
A5: Average Revenue Per User (ARPU, $/mo) | B5: Inputs!$B$31
A6: Monthly Churn Rate | B6: Inputs!$B$60
A7: Gross Margin | B7: Inputs!$B$62
A8: Customer Lifetime (months) | B8: =IF(B6=0,0,1/B6)
A9: Lifetime Revenue ($) | B9: =B5*B8
A10: LTV (Gross Profit, $) | B10: =B9*B7
A11: CAC ($) | B11: Inputs!$B$57
A12: LTV/CAC Ratio | B12: =IF(B11=0,0,B10/B11)
A13: Payback Period (months) | B13: =IF(B5=0,0,B11/(B5*B7))
A16: ENTERPRISE TIER
A18: Average Contract Value ($/yr) | B18: Inputs!$B$30
A19: Monthly Churn Rate | B19: Inputs!$B$61
A20: Gross Margin | B20: Inputs!$B$62
A21: Customer Lifetime (months) | B21: =IF(B19=0,0,1/B19)
A22: Lifetime Revenue ($) | B22: =B18/12*B21
A23: LTV (Gross Profit, $) | B23: =B22*B20
A24: CAC ($) | B24: Inputs!$B$58
A25: LTV/CAC Ratio | B25: =IF(B24=0,0,B23/B24)
A26: Payback Period (months) | B26: =IF(B18=0,0,B24/(B18/12*B20))
A29: UNIT ECONOMICS COMPARISON
A31: Metric | B31: Team | C31: Enterprise
A32: ARPU / ACV | B32: =B5 | C32: =B18
A33: Churn (%) | B33: =B6 | C33: =B19
A34: Gross Margin (%) | B34: =B7 | C34: =B20
A35: Lifetime (mo) | B35: =B8 | C35: =B21
A36: LTV ($) | B36: =B10 | C36: =B23
A37: CAC ($) | B37: =B11 | C37: =B24
A38: LTV/CAC (x) | B38: =B12 | C38: =B25
A39: Payback (mo) | B39: =B13 | C39: =B26

Sheet Checks
A1: BALANCE CHECKS & RECONCILIATION
A3: BALANCE SHEET BALANCE (Assets = Liabilities + Equity)
A5: Year | B5: Year 1 | C5: Year 2 | D5: Year 3 | E5: Year 4 | F5: Year 5
A7: Cash & Equivalents | B7: ='5-Year Projection'!B36+100000 | C7: =B7+'5-Year Projection'!C36 | D7: =C7+'5-Year Projection'!D36 | E7: =D7+'5-Year Projection'!E36 | F7: =E7+'5-Year Projection'!F36
A8: Accounts Receivable | B8: ='5-Year Projection'!B15*0.15 | C8: ='5-Year Projection'!C15*0.15 | D8: ='5-Year Projection'!D15*0.15 | E8: ='5-Year Projection'!E15*0.15 | F8: ='5-Year Projection'!F15*0.15
A9: Total Assets | B9: =B7+B8 | C9: =C7+C8 | D9: =D7+D8 | E9: =E7+E8 | F9: =F7+F8
A11: Accounts Payable | B11: ='5-Year Projection'!B26*0.10 | C11: ='5-Year Projection'!C26*0.10 | D11: ='5-Year Projection'!D26*0.10 | E11: ='5-Year Projection'!E26*0.10 | F11: ='5-Year Projection'!F26*0.10
A12: Deferred Revenue | B12: ='5-Year Projection'!B15*0.20 | C12: ='5-Year Projection'!C15*0.20 | D12: ='5-Year Projection'!D15*0.20 | E12: ='5-Year Projection'!E15*0.20 | F12: ='5-Year Projection'!F15*0.20
A13: Total Liabilities | B13: =B11+B12 | C13: =C11+C12 | D13: =D11+D12 | E13: =E11+E12 | F13: =F11+F12
A15: Retained Earnings | B15: ='5-Year Projection'!B36 | C15: =B15+'5-Year Projection'!C36 | D15: =C15+'5-Year Projection'!D36 | E15: =D15+'5-Year Projection'!E36 | F15: =E15+'5-Year Projection'!F36
A16: Total Equity | B16: =B15 | C16: =C15 | D16: =D15 | E16: =E15 | F16: =F15
A18: Total Liabilities + Equity | B18: =B13+B16 | C18: =C13+C16 | D18: =D13+D16 | E18: =E13+E16 | F18: =F13+F16
A20: BS Balance Check (Assets - L&E = 0) | B20: =B9-B18 | C20: =C9-C18 | D20: =D9-D18 | E20: =E9-E18 | F20: =F9-F18
A21: BS Balanced? | B21: =ABS(B20)<0.01 | C21: =ABS(C20)<0.01 | D21: =ABS(D20)<0.01 | E21: =ABS(E20)<0.01 | F21: =ABS(F20)<0.01
A24: CASH FLOW RECONCILIATION
A26: Year | B26: Year 1 | C26: Year 2 | D26: Year 3 | E26: Year 4 | F26: Year 5
A28: Net Income | B28: ='5-Year Projection'!B36 | C28: ='5-Year Projection'!C36 | D28: ='5-Year Projection'!D36 | E28: ='5-Year Projection'!E36 | F28: ='5-Year Projection'!F36
A29: Depreciation Add-Back | B29: ='5-Year Projection'!B31 | C29: ='5-Year Projection'!C31 | D29: ='5-Year Projection'!D31 | E29: ='5-Year Projection'!E31 | F29: ='5-Year Projection'!F31
A30: Change in Working Capital | B30: =-'5-Year Projection'!B15*0.05 | C30: =-'5-Year Projection'!C15*0.05 | D30: =-'5-Year Projection'!D15*0.05 | E30: =-'5-Year Projection'!E15*0.05 | F30: =-'5-Year Projection'!F15*0.05
A31: Operating Cash Flow | B31: =B28+B29+B30 | C31: =C28+C29+C30 | D31: =D28+D29+D30 | E31: =E28+E29+E30 | F31: =F28+F29+F30
A33: Cash Flow = Cash Change? | B33: =ABS(B31-(B7-100000))<1 | C33: =ABS(C31-(C7-B7))<1 | D33: =ABS(D31-(D7-C7))<1 | E33: =ABS(E31-(E7-D7))<1 | F33: =ABS(F31-(F7-E7))<1
A36: REVENUE CROSS-CHECK: P&L vs PRICING MODEL
A38: Year | B38: Year 1 | C38: Year 2 | D38: Year 3 | E38: Year 4 | F38: Year 5
A40: Revenue from P&L | B40: ='5-Year Projection'!B15 | C40: ='5-Year Projection'!C15 | D40: ='5-Year Projection'!D15 | E40: ='5-Year Projection'!E15 | F40: ='5-Year Projection'!F15
A41: Revenue from Pricing Sheet | B41: ='Pricing Model'!B25 | C41: ='Pricing Model'!C25 | D41: ='Pricing Model'!D25 | E41: ='Pricing Model'!E25 | F41: ='Pricing Model'!F25
A42: Difference | B42: =B40-B41 | C42: =C40-C41 | D42: =D40-D41 | E42: =E40-E41 | F42: =F40-F41
A43: Tied? | B43: =ABS(B42)<0.01 | C43: =ABS(C42)<0.01 | D43: =ABS(D42)<0.01 | E43: =ABS(E42)<0.01 | F43: =ABS(F42)<0.01
A46: ROGUE HARDCODE CHECK
A48: All P&L cells are formulas? | B48: Manual review required
A49: Named ranges defined? | B49: See Defined Names
A50: Inputs all blue (#0000FF)? | B50: Manual review required
A52: KEY FIGURES (Named Range Targets)
A54: Market CAGR | B54: Inputs!$B$8
A55: Discount Rate | B55: Inputs!$B$42
A56: Revenue Y5 | B56: '5-Year Projection'!F$15
A57: EBITDA Y5 | B57: '5-Year Projection'!F$28
A58: Net Income Y5 | B58: '5-Year Projection'!F$36
A59: Team ARPU | B59: Inputs!$B$31
A60: Enterprise ACV | B60: Inputs!$B$30
A61: Gross Margin | B61: Inputs!$B$37
...
